<?xml version="1.0"?>

<robot xmlns:xacro="http://ros.org/wiki/xacro">
  <xacro:property name="M_PI" value="3.14159"/>
  <xacro:property name="SCALE_MM" value="0.001"/>
  <xacro:property name="SCALE_CM" value="0.01"/>

  <xacro:property name="NAME_JOINT_BASE" value="crane_x7_shoulder_fixed_part_mount_joint"/>
  <xacro:property name="NAME_JOINT_1" value="crane_x7_shoulder_fixed_part_pan_joint"/>
  <xacro:property name="NAME_JOINT_2" value="crane_x7_shoulder_revolute_part_tilt_joint"/>
  <xacro:property name="NAME_JOINT_3" value="crane_x7_upper_arm_revolute_part_twist_joint"/>
  <xacro:property name="NAME_JOINT_4" value="crane_x7_upper_arm_revolute_part_rotate_joint"/>
  <xacro:property name="NAME_JOINT_5" value="crane_x7_lower_arm_fixed_part_joint"/>
  <xacro:property name="NAME_JOINT_6" value="crane_x7_lower_arm_revolute_part_joint"/>
  <xacro:property name="NAME_JOINT_7" value="crane_x7_wrist_joint"/>

  <xacro:property name="NAME_LINK_BASE" value="crane_x7_shoulder_fixed_part_link"/>
  <xacro:property name="NAME_LINK_1" value="crane_x7_shoulder_revolute_part_link"/>
  <xacro:property name="NAME_LINK_2" value="crane_x7_upper_arm_fixed_part_link"/>
  <xacro:property name="NAME_LINK_3" value="crane_x7_upper_arm_revolute_part_link"/>
  <xacro:property name="NAME_LINK_4" value="crane_x7_lower_arm_fixed_part_link"/>
  <xacro:property name="NAME_LINK_5" value="crane_x7_lower_arm_revolute_part_link"/>
  <xacro:property name="NAME_LINK_6" value="crane_x7_wrist_link"/>

  <xacro:property name="NAME_JOINT_COVER_2_L" value="crane_x7_upper_arm_fixed_part_joint_cover_l_joint"/>
  <xacro:property name="NAME_JOINT_COVER_2_R" value="crane_x7_upper_arm_fixed_part_joint_cover_r_joint"/>
  <xacro:property name="NAME_JOINT_COVER_4_L" value="crane_x7_lower_arm_fixed_part_joint_cover_l_joint"/>
  <xacro:property name="NAME_JOINT_COVER_4_R" value="crane_x7_lower_arm_fixed_part_joint_cover_r_joint"/>

  <xacro:property name="NAME_LINK_COVER_2_L" value="crane_x7_upper_arm_fixed_part_joint_cover_l_link"/>
  <xacro:property name="NAME_LINK_COVER_2_R" value="crane_x7_upper_arm_fixed_part_joint_cover_r_link"/>
  <xacro:property name="NAME_LINK_COVER_4_L" value="crane_x7_lower_arm_fixed_part_joint_cover_l_link"/>
  <xacro:property name="NAME_LINK_COVER_4_R" value="crane_x7_lower_arm_fixed_part_joint_cover_r_link"/>

  <xacro:property name="NAME_LOGO" value="crane_x7_lower_arm_revolute_part"/>

  <!-- Macro for the standard CRANE-X7 configuration -->
  <xacro:macro name="crane_x7_arm"
      params="parent
              end_effector_base_link
              base_color
              shoulder_color
              shoulder_joint_cover_color
              upper_arm_upper_color
              upper_arm_lower_color
              elbow_joint_cover_color
              lower_arm_upper_color
              lower_arm_lower_color
              wrist_color
              joints_vlimit
              shoulder_llimit
              shoulder_ulimit
              logos_definition
              *origin">

    <!-- crane_x7_joint_base -->
    <joint name="${NAME_JOINT_BASE}" type="fixed">
      <xacro:insert_block name="origin"/>
      <parent link="${parent}"/>
      <child link="${NAME_LINK_BASE}"/>
    </joint>

    <!-- crane_x7_link_base -->
    <link name="${NAME_LINK_BASE}">
      <visual>
        <origin xyz="0 0 0" rpy="0 0 0"/>
        <geometry>
          <mesh filename="package://crane_x7_description/meshes/visual/base_fixed_part.stl"
              scale="1 1 1"/>
        </geometry>
        <material name="${base_color}"/>
      </visual>

      <collision>
        <origin xyz="0 0 0" rpy="0 0 0"/>
        <geometry>
          <mesh filename="package://crane_x7_description/meshes/collision/base_fixed_part.stl"
              scale="1 1 1"/>
        </geometry>
      </collision>

      <inertial>
        <mass value="0.388"/>
        <origin xyz="-6.73E-03 -1.00E-06 1.79E-02" rpy="0 0 0"/>
        <inertia ixx="3.25E-04" ixy="1.20E-09" ixz="-4.71E-05"
          iyy="4.83E-04" iyz="1.95E-08"
          izz="5.86E-04"/>
      </inertial>
    </link>

    <!-- crane_x7_joint_1 -->
    <joint name="${NAME_JOINT_1}" type="revolute">
      <origin xyz="0 0 0.036" rpy="0 0 0"/>
      <axis xyz="0 0 1"/>
      <limit effort="10.0" velocity="${joints_vlimit}" lower="${shoulder_llimit}" upper="${shoulder_ulimit}"/>
      <parent link="${NAME_LINK_BASE}"/>
      <child link="${NAME_LINK_1}"/>
      <dynamics damping="1.0e-6" friction="2.0e-1"/>
    </joint>

    <!-- For gazebo simulation -->
    <transmission name="${NAME_JOINT_1}_trans">
      <provideFeedback>true</provideFeedback>
      <implicitSpringDamper>0</implicitSpringDamper>
      <motorTorqueConstant>0.418</motorTorqueConstant>
      <type>transmission_interface/SimpleTransmission</type>
      <joint name="${NAME_JOINT_1}">
        <hardwareInterface>hardware_interface/PositionJointInterface</hardwareInterface>
      </joint>
      <actuator name="${NAME_JOINT_1}_motor">
        <hardwareInterface>hardware_interface/PositionJointInterface</hardwareInterface>
        <mechanicalReduction>1</mechanicalReduction>
      </actuator>
    </transmission>

    <!-- crane_x7_link_1 -->
    <link name="${NAME_LINK_1}">
      <visual>
        <origin xyz="0 0 0" rpy="0 0 ${M_PI}"/>
        <geometry>
          <mesh filename="package://crane_x7_description/meshes/visual/base_revolute_part.stl"
              scale="1 1 1"/>
        </geometry>
        <material name="${shoulder_color}"/>
      </visual>

      <collision>
        <!--<origin xyz="0 0 0" rpy="0 0 ${M_PI}"/>-->
        <!--<geometry>-->
          <!--<mesh filename="package://crane_x7_description/meshes/collision/base_revolute_part.stl"-->
              <!--scale="1 1 1"/>-->
        <!--</geometry>-->
        <origin xyz="0 0 0.0296" rpy="0 0 0"/>
        <geometry>
          <cylinder radius="0.0334" length="0.0295"/>
        </geometry>
      </collision>
      <collision>
        <origin xyz="0 0 0.064" rpy="${M_PI/2} 0 0"/>
        <geometry>
          <cylinder radius="0.034" length="0.0491"/>
        </geometry>
      </collision>

      <inertial>
        <mass value="0.253"/>
        <origin xyz="2.43e-04 -1.05E-04 4.70E-02" rpy="0 0 0"/>
        <inertia ixx="1.79E-04" ixy="-7.32E-08" ixz="8.89E-07"
          iyy="1.76E-04" iyz="6.23E-07"
          izz="8.96E-05"/>
      </inertial>
    </link>

    <!-- crane_x7_joint_2 -->
    <joint name="${NAME_JOINT_2}" type="revolute">
      <origin xyz="0 0 0.064" rpy="0 0 0"/>
      <axis xyz="0 -1 0"/>
      <limit effort="10.0" velocity="${joints_vlimit}" lower="-${M_PI/2}" upper="${M_PI/2}"/>
      <parent link="${NAME_LINK_1}"/>
      <child link="${NAME_LINK_2}"/>
      <dynamics damping="1.0e-6" friction="2.0e-1"/>
    </joint>

    <!-- For gazebo simulation -->
    <transmission name="${NAME_JOINT_2}_trans">
      <provideFeedback>true</provideFeedback>
      <implicitSpringDamper>0</implicitSpringDamper>
      <motorTorqueConstant>0.418</motorTorqueConstant>
      <type>transmission_interface/SimpleTransmission</type>
      <joint name="${NAME_JOINT_2}">
        <hardwareInterface>hardware_interface/PositionJointInterface</hardwareInterface>
      </joint>
      <actuator name="${NAME_JOINT_2}_motor">
        <hardwareInterface>hardware_interface/PositionJointInterface</hardwareInterface>
        <mechanicalReduction>1</mechanicalReduction>
      </actuator>
    </transmission>

    <!-- crane_x7_link_2 -->
    <link name="${NAME_LINK_2}">
      <visual>
        <origin xyz="0 0 0" rpy="${M_PI/2} 0 0"/>
        <geometry>
          <mesh filename="package://crane_x7_description/meshes/visual/rotating_link_type_1_fixed_part.stl"
              scale="1 1 1"/>
        </geometry>
        <material name="${upper_arm_upper_color}"/>
      </visual>

      <collision>
        <origin xyz="0 0 0" rpy="${M_PI/2} 0 0"/>
        <geometry>
          <mesh filename="package://crane_x7_description/meshes/collision/rotating_link_type_1_fixed_part.stl"
              scale="1 1 1"/>
        </geometry>
      </collision>

      <inertial>
        <mass value="0.136"/>
        <origin xyz="3.10E-05 1.90E-05 3.42E-02" rpy="${M_PI/2} 0 0"/>
        <inertia ixx="1.68E-04" ixy="2.05E-08" ixz="-4.00E-07"
          iyy="9.62E-05" iyz="6.24E-08"
          izz="1.34E-04"/>
      </inertial>
    </link>

    <!-- crane_x7_joint_cover_2_l -->
    <joint name="${NAME_JOINT_COVER_2_L}" type="fixed">
      <parent link="${NAME_LINK_2}"/>
      <child link="${NAME_LINK_COVER_2_L}"/>
      <origin xyz="0 0.0316 0" rpy="0 0 0"/>
    </joint>

    <!-- crane_x7_link_cover_2_l -->
    <link name="${NAME_LINK_COVER_2_L}">
      <visual>
        <origin xyz="0 0 0" rpy="-${M_PI/2} 0 0"/>
        <geometry>
          <mesh filename="package://crane_x7_description/meshes/visual/joint_cover.stl"
              scale="1 1 1"/>
        </geometry>
        <material name="${shoulder_joint_cover_color}"/>
      </visual>
    </link>

    <!-- crane_x7_joint_cover_2_r -->
    <joint name="${NAME_JOINT_COVER_2_R}" type="fixed">
      <parent link="${NAME_LINK_2}"/>
      <child link="${NAME_LINK_COVER_2_R}"/>
      <origin xyz="0 -0.0316 0" rpy="0 0 0"/>
    </joint>

    <!-- crane_x7_link_cover_2_r -->
    <link name="${NAME_LINK_COVER_2_R}">
      <visual>
        <origin xyz="0 0 0" rpy="${M_PI/2} 0 0"/>
        <geometry>
          <mesh filename="package://crane_x7_description/meshes/visual/joint_cover.stl"
              scale="1 1 1"/>
        </geometry>
        <material name="${shoulder_joint_cover_color}"/>
      </visual>
    </link>

    <!-- crane_x7_joint_3 -->
    <joint name="${NAME_JOINT_3}" type="revolute">
      <origin xyz="0 0 0.065" rpy="0 0 0"/>
      <axis xyz="0 0 1"/>
      <limit effort="4.0"
          velocity="${joints_vlimit}"
          lower="-${M_PI/2}"
          upper="${M_PI/2}"/>
      <parent link="${NAME_LINK_2}"/>
      <child link="${NAME_LINK_3}"/>
      <dynamics damping="1.0e-6" friction="2.0e-1"/>
    </joint>

    <!-- For gazebo simulation -->
    <transmission name="${NAME_JOINT_3}_trans">
      <provideFeedback>true</provideFeedback>
      <implicitSpringDamper>0</implicitSpringDamper>
      <motorTorqueConstant>0.418</motorTorqueConstant>
      <type>transmission_interface/SimpleTransmission</type>
      <joint name="${NAME_JOINT_3}">
        <hardwareInterface>hardware_interface/PositionJointInterface</hardwareInterface>
      </joint>
      <actuator name="${NAME_JOINT_3}_motor">
        <hardwareInterface>hardware_interface/PositionJointInterface</hardwareInterface>
        <mechanicalReduction>1</mechanicalReduction>
      </actuator>
    </transmission>

    <!-- crane_x7_link_3 -->
    <link name="${NAME_LINK_3}">
      <visual>
        <origin xyz="0 0 0" rpy="0 0 0"/>
        <geometry>
          <mesh filename="package://crane_x7_description/meshes/visual/rotating_link_type_1_revolute_part.stl"
              scale="1 1 1"/>
        </geometry>
        <material name="${upper_arm_lower_color}"/>
      </visual>

      <collision>
        <origin xyz="0 0 0" rpy="0 0 0"/>
        <geometry>
          <mesh filename="package://crane_x7_description/meshes/collision/rotating_link_type_1_revolute_part.stl"
              scale="1 1 1"/>
        </geometry>
      </collision>

      <inertial>
        <mass value="0.321"/>
        <origin xyz="-1.37E-02 -8.10E-05 9.52E-02" rpy="0 0 0"/>
        <inertia ixx="1.82E-03" ixy="7.54E-07" ixz="-3.73E-05"
          iyy="1.88E-03" iyz="4.15E-06"
          izz="1.59E-04"/>
      </inertial>
    </link>

    <!-- crane_x7_joint_4 -->
    <joint name="${NAME_JOINT_4}" type="revolute">
      <origin xyz="0 0 0.185" rpy="0 0 0"/>
      <axis xyz="0 -1 0"/>
      <limit effort="4.0"
          velocity="${joints_vlimit}"
          lower="-2.80718"
          upper="0.04141"/>
      <parent link="${NAME_LINK_3}"/>
      <child link="${NAME_LINK_4}"/>
      <dynamics damping="1.0e-6" friction="2.0e-1"/>
    </joint>

    <!-- For gazebo simulation -->
    <transmission name="${NAME_JOINT_4}_trans">
      <provideFeedback>true</provideFeedback>
      <implicitSpringDamper>0</implicitSpringDamper>
      <motorTorqueConstant>0.418</motorTorqueConstant>
      <type>transmission_interface/SimpleTransmission</type>
      <joint name="${NAME_JOINT_4}">
        <hardwareInterface>hardware_interface/PositionJointInterface</hardwareInterface>
      </joint>
      <actuator name="${NAME_JOINT_4}_motor">
        <hardwareInterface>hardware_interface/PositionJointInterface</hardwareInterface>
        <mechanicalReduction>1</mechanicalReduction>
      </actuator>
    </transmission>

    <!-- crane_x7_link_4 -->
    <link name="${NAME_LINK_4}">
      <visual>
        <origin xyz="0 0 0" rpy="${M_PI/2} 0 0"/>
        <geometry>
          <mesh filename="package://crane_x7_description/meshes/visual/rotating_link_type_2_fixed_part.stl"
              scale="1 1 1"/>
        </geometry>
        <material name="${lower_arm_upper_color}"/>
      </visual>

      <collision>
        <origin xyz="0 0 0" rpy="${M_PI/2} 0 0"/>
        <geometry>
          <mesh filename="package://crane_x7_description/meshes/collision/rotating_link_type_2_fixed_part.stl"
              scale="1 1 1"/>
        </geometry>
      </collision>

      <inertial>
        <mass value="0.222"/>
        <origin xyz="-9.39E-03 6.40E-05 8.04E-02" rpy="${M_PI/2} 0 0"/>
        <inertia ixx="4.89E-04" ixy="-3.90E-06" ixz="8.29E-08"
          iyy="1.14E-04" iyz="2.82E-06"
          izz="5.03E-04"/>
      </inertial>
    </link>

    <!-- crane_x7_joint_cover_4_l -->
    <joint name="${NAME_JOINT_COVER_4_L}" type="fixed">
      <parent link="${NAME_LINK_4}"/>
      <child link="${NAME_LINK_COVER_4_L}"/>
      <origin xyz="0 0.025 0" rpy="0 0 0"/>
    </joint>

    <!-- crane_x7_link_cover_4_l -->
    <link name="${NAME_LINK_COVER_4_L}">
      <visual>
        <origin xyz="0 0 0" rpy="-${M_PI/2} 0 0"/>
        <geometry>
          <mesh filename="package://crane_x7_description/meshes/visual/joint_cover.stl"
              scale="1 1 1"/>
        </geometry>
        <material name="${elbow_joint_cover_color}"/>
      </visual>
    </link>

    <!-- crane_x7_joint_cover_4_r -->
    <joint name="${NAME_JOINT_COVER_4_R}" type="fixed">
      <parent link="${NAME_LINK_4}"/>
      <child link="${NAME_LINK_COVER_4_R}"/>
      <origin xyz="0 -0.025 0" rpy="0 0 0"/>
    </joint>

    <!-- crane_x7_link_cover_4_r -->
    <link name="${NAME_LINK_COVER_4_R}">
      <visual>
        <origin xyz="0 0 0" rpy="${M_PI/2} 0 0"/>
        <geometry>
          <mesh filename="package://crane_x7_description/meshes/visual/joint_cover.stl"
              scale="1 1 1"/>
        </geometry>
        <material name="${elbow_joint_cover_color}"/>
      </visual>
    </link>

    <!-- crane_x7_joint_5 -->
    <joint name="${NAME_JOINT_5}" type="revolute">
      <origin xyz="0 0 0.121" rpy="0 0 0"/>
      <axis xyz="0 0 1"/>
      <limit effort="4.0" velocity="${joints_vlimit}" lower="-2.77343" upper="1.51403"/>
      <parent link="${NAME_LINK_4}"/>
      <child link="${NAME_LINK_5}"/>
      <dynamics damping="1.0e-6" friction="2.0e-1"/>
    </joint>

    <!-- For gazebo simulation -->
    <transmission name="${NAME_JOINT_5}_trans">
      <provideFeedback>true</provideFeedback>
      <implicitSpringDamper>0</implicitSpringDamper>
      <motorTorqueConstant>0.418</motorTorqueConstant>
      <type>transmission_interface/SimpleTransmission</type>
      <joint name="${NAME_JOINT_5}">
        <hardwareInterface>hardware_interface/PositionJointInterface</hardwareInterface>
      </joint>
      <actuator name="${NAME_JOINT_5}_motor">
        <hardwareInterface>hardware_interface/PositionJointInterface</hardwareInterface>
        <mechanicalReduction>1</mechanicalReduction>
      </actuator>
    </transmission>

    <!-- crane_x7_link_5 -->
    <link name="${NAME_LINK_5}">
      <visual>
        <origin xyz="0 0 0" rpy="0 0 0"/>
        <geometry>
          <mesh filename="package://crane_x7_description/meshes/visual/rotating_link_type_2_revolute_part.stl"
              scale="1 1 1"/>
        </geometry>
        <material name="${lower_arm_lower_color}"/>
      </visual>

      <collision>
        <origin xyz="0 0 0" rpy="0 0 0"/>
        <geometry>
          <mesh filename="package://crane_x7_description/meshes/collision/rotating_link_type_2_revolute_part.stl"
              scale="1 1 1"/>
        </geometry>
      </collision>

      <inertial>
        <mass value="0.207"/>
        <origin xyz="-8.40E-05 4.62E-04 6.37E-02" rpy="0 0 0"/>
        <inertia ixx="2.90E-04" ixy="1.00E-07" ixz="-4.77E-07"
          iyy="2.57E-04" iyz="-1.69E-05"
          izz="8.75E-05"/>
      </inertial>
    </link>

    <!-- logo -->
    <xacro:include filename="${logos_definition}"/>
    <crane_x7_logos 
      parent="${NAME_LINK_5}"
      name="${NAME_LOGO}"/>

    <!-- crane_x7_joint_6 -->
    <joint name="${NAME_JOINT_6}" type="revolute">
      <origin xyz="0 0 0.129" rpy="0 0 0"/>
      <axis xyz="0 -1 0"/>
      <limit effort="4.0" velocity="${joints_vlimit}" lower="-${M_PI/2}" upper="${M_PI/2}"/>
      <parent link="${NAME_LINK_5}"/>
      <child link="${NAME_LINK_6}"/>
      <dynamics damping="1.0e-6" friction="2.0e-1"/>
    </joint>

    <!-- For gazebo simulation -->
    <transmission name="${NAME_JOINT_6}_trans">
      <provideFeedback>true</provideFeedback>
      <implicitSpringDamper>0</implicitSpringDamper>
      <motorTorqueConstant>0.418</motorTorqueConstant>
      <type>transmission_interface/SimpleTransmission</type>
      <joint name="${NAME_JOINT_6}">
        <hardwareInterface>hardware_interface/PositionJointInterface</hardwareInterface>
      </joint>
      <actuator name="${NAME_JOINT_6}_motor">
        <hardwareInterface>hardware_interface/PositionJointInterface</hardwareInterface>
        <mechanicalReduction>1</mechanicalReduction>
      </actuator>
    </transmission>

    <!-- crane_x7_link_6 -->
    <link name="${NAME_LINK_6}">
      <visual>
        <origin xyz="0 0 0" rpy="${M_PI/2} 0 0"/>
        <geometry>
          <mesh filename="package://crane_x7_description/meshes/visual/wrist.stl"
              scale="1 1 1"/>
        </geometry>
        <material name="${wrist_color}"/>
      </visual>

      <collision>
        <origin xyz="0 0 0" rpy="${M_PI/2} 0 0"/>
        <geometry>
          <mesh filename="package://crane_x7_description/meshes/collision/wrist.stl"
              scale="1 1 1"/>
        </geometry>
      </collision>

      <inertial>
        <mass value="0.14"/>
        <origin xyz="6.10E-03 8.26E-04 -3.55E-03" rpy="${M_PI/2} 0 0"/>
        <inertia ixx="4.01E-05" ixy="-2.91E-06" ixz="6.39E-07"
          iyy="6.13E-05" iyz="-4.90E-07"
          izz="7.35E-05"/>
      </inertial>
    </link>

    <!-- crane_x7_joint_7 -->
    <joint name="${NAME_JOINT_7}" type="revolute">
      <origin xyz="0 0 0.019" rpy="0 0 0"/>
      <axis xyz="0 0 1"/>
      <limit effort="4.0" velocity="${joints_vlimit}" lower="-2.96365" upper="2.97132"/>
      <parent link="${NAME_LINK_6}"/>
      <child link="${end_effector_base_link}"/>
      <dynamics damping="1.0e-6" friction="2.0e-1"/>
    </joint>

    <!-- For gazebo simulation -->
    <transmission name="${NAME_JOINT_7}_trans">
      <provideFeedback>true</provideFeedback>
      <implicitSpringDamper>0</implicitSpringDamper>
      <motorTorqueConstant>0.418</motorTorqueConstant>
      <type>transmission_interface/SimpleTransmission</type>
      <joint name="${NAME_JOINT_7}">
        <hardwareInterface>hardware_interface/PositionJointInterface</hardwareInterface>
      </joint>
      <actuator name="${NAME_JOINT_7}_motor">
        <hardwareInterface>hardware_interface/PositionJointInterface</hardwareInterface>
        <mechanicalReduction>1</mechanicalReduction>
      </actuator>
    </transmission>

    <gazebo>
      <plugin name='gazebo_ros_control' filename='libgazebo_ros_control.so'>
        <robotNamespace>/crane_x7</robotNamespace>
        <robotSimType>gazebo_ros_control/DefaultRobotHWSim</robotSimType>
        <legacyModeNS>false</legacyModeNS>
      </plugin>
    </gazebo>

    <gazebo reference="${NAME_LINK_BASE}">
      <material>Gazebo/Red</material>
    </gazebo>
    <gazebo reference="${NAME_LINK_1}">
      <material>Gazebo/White</material>
    </gazebo>
    <gazebo reference="${NAME_LINK_2}">
      <material>Gazebo/White</material>
    </gazebo>
    <gazebo reference="${NAME_LINK_3}">
      <material>Gazebo/White</material>
    </gazebo>
    <gazebo reference="${NAME_LINK_4}">
      <material>Gazebo/White</material>
    </gazebo>
    <gazebo reference="${NAME_LINK_5}">
      <material>Gazebo/White</material>
    </gazebo>
    <gazebo reference="${NAME_LINK_6}">
      <material>Gazebo/White</material>
    </gazebo>
    <gazebo reference="${NAME_LINK_COVER_2_L}">
      <material>Gazebo/Red</material>
    </gazebo>
    <gazebo reference="${NAME_LINK_COVER_2_R}">
      <material>Gazebo/Red</material>
    </gazebo>
    <gazebo reference="${NAME_LINK_COVER_4_L}">
      <material>Gazebo/Red</material>
    </gazebo>
    <gazebo reference="${NAME_LINK_COVER_4_R}">
      <material>Gazebo/Red</material>
    </gazebo>

  </xacro:macro>

</robot>
