<?xml version="1.0" encoding="utf-8"?>
<!-- =================================================================================== -->
<!-- |    This document was autogenerated by xacro from crane_x7_description/urdf/crane_x7.urdf.xacro | -->
<!-- |    EDITING THIS FILE BY HAND IS NOT RECOMMENDED                                 | -->
<!-- =================================================================================== -->
<robot name="crane_x7" xmlns:controller="http://playerstage.sourceforge.net/gazebo/xmlschema/#controller" xmlns:interface="http://playerstage.sourceforge.net/gazebo/xmlschema/#interface" xmlns:sensor="http://playerstage.sourceforge.net/gazebo/xmlschema/#sensor">
  <material name="black">
    <color rgba="0.2 0.2 0.2 1.0"/>
  </material>
  <material name="white">
    <color rgba="0.95 0.95 0.95 1.0"/>
  </material>
  <material name="silver">
    <color rgba="0.75 0.75 0.75 1.0"/>
  </material>
  <material name="red">
    <color rgba="1.0 0.3 0.3 1.0"/>
  </material>
  <material name="green">
    <color rgba="0.3 1.0 0.3 1.0"/>
  </material>
  <material name="blue">
    <color rgba="0.3 0.3 1.0 1.0"/>
  </material>
  <!-- Link to provide the location reference for the arm -->
  <link name="base_link"/>
  <!-- Used for fixing robot to Gazebo 'base_link' -->
  <link name="world"/>
  <joint name="base_link_to_world_joint" type="fixed">
    <parent link="world"/>
    <child link="base_link"/>
  </joint>
  <joint name="crane_x7_mounting_plate_joint" type="fixed">
    <origin xyz="0 0 0"/>
    <parent link="base_link"/>
    <child link="crane_x7_mounting_plate_link"/>
  </joint>
  <link name="crane_x7_mounting_plate_link">
    <visual>
      <origin rpy="0 0 0" xyz="0 0 0"/>
      <geometry>
        <mesh filename="package://crane_x7_description/meshes/visual/mounting_plate.stl" scale="1 1 1"/>
      </geometry>
      <material name="silver"/>
    </visual>
    <collision>
      <origin rpy="0 0 0" xyz="0 0 0"/>
      <geometry>
        <mesh filename="package://crane_x7_description/meshes/collision/mounting_plate.stl" scale="1 1 1"/>
      </geometry>
    </collision>
  </link>
  <!-- For gazebo simulation -->
  <gazebo reference="crane_x7_mounting_plate_link">
    <material>Gazebo/Black</material>
  </gazebo>
  <!-- crane_x7_joint_base -->
  <joint name="crane_x7_shoulder_fixed_part_mount_joint" type="fixed">
    <origin rpy="0 0 0" xyz="0 0 0.005"/>
    <parent link="crane_x7_mounting_plate_link"/>
    <child link="crane_x7_shoulder_fixed_part_link"/>
  </joint>
  <!-- crane_x7_link_base -->
  <link name="crane_x7_shoulder_fixed_part_link">
    <visual>
      <origin rpy="0 0 0" xyz="0 0 0"/>
      <geometry>
        <mesh filename="package://crane_x7_description/meshes/visual/base_fixed_part.stl" scale="1 1 1"/>
      </geometry>
      <material name="red"/>
    </visual>
    <collision>
      <origin rpy="0 0 0" xyz="0 0 0"/>
      <geometry>
        <mesh filename="package://crane_x7_description/meshes/collision/base_fixed_part.stl" scale="1 1 1"/>
      </geometry>
    </collision>
    <inertial>
      <mass value="0.388"/>
      <origin rpy="0 0 0" xyz="-6.73E-03 -1.00E-06 1.79E-02"/>
      <inertia ixx="3.25E-04" ixy="1.20E-09" ixz="-4.71E-05" iyy="4.83E-04" iyz="1.95E-08" izz="5.86E-04"/>
    </inertial>
  </link>
  <!-- crane_x7_joint_1 -->
  <joint name="crane_x7_shoulder_fixed_part_pan_joint" type="revolute">
    <origin rpy="0 0 0" xyz="0 0 0.036"/>
    <axis xyz="0 0 1"/>
    <limit effort="10.0" lower="-2.97132" upper="2.97132" velocity="4.81710873"/>
    <parent link="crane_x7_shoulder_fixed_part_link"/>
    <child link="crane_x7_shoulder_revolute_part_link"/>
    <dynamics damping="1.0e-6" friction="2.0e-1"/>
  </joint>
  <!-- For gazebo simulation -->
  <transmission name="crane_x7_shoulder_fixed_part_pan_joint_trans">
    <provideFeedback>true</provideFeedback>
    <implicitSpringDamper>0</implicitSpringDamper>
    <motorTorqueConstant>0.418</motorTorqueConstant>
    <type>transmission_interface/SimpleTransmission</type>
    <joint name="crane_x7_shoulder_fixed_part_pan_joint">
      <hardwareInterface>hardware_interface/PositionJointInterface</hardwareInterface>
    </joint>
    <actuator name="crane_x7_shoulder_fixed_part_pan_joint_motor">
      <hardwareInterface>hardware_interface/PositionJointInterface</hardwareInterface>
      <mechanicalReduction>1</mechanicalReduction>
    </actuator>
  </transmission>
  <!-- crane_x7_link_1 -->
  <link name="crane_x7_shoulder_revolute_part_link">
    <visual>
      <origin rpy="0 0 3.14159" xyz="0 0 0"/>
      <geometry>
        <mesh filename="package://crane_x7_description/meshes/visual/base_revolute_part.stl" scale="1 1 1"/>
      </geometry>
      <material name="white"/>
    </visual>
    <collision>
      <!--<origin xyz="0 0 0" rpy="0 0 ${M_PI}"/>-->
      <!--<geometry>-->
      <!--<mesh filename="package://crane_x7_description/meshes/collision/base_revolute_part.stl"-->
      <!--scale="1 1 1"/>-->
      <!--</geometry>-->
      <origin rpy="0 0 0" xyz="0 0 0.0296"/>
      <geometry>
        <cylinder length="0.0295" radius="0.0334"/>
      </geometry>
    </collision>
    <collision>
      <origin rpy="1.570795 0 0" xyz="0 0 0.064"/>
      <geometry>
        <cylinder length="0.0491" radius="0.034"/>
      </geometry>
    </collision>
    <inertial>
      <mass value="0.253"/>
      <origin rpy="0 0 0" xyz="2.43e-04 -1.05E-04 4.70E-02"/>
      <inertia ixx="1.79E-04" ixy="-7.32E-08" ixz="8.89E-07" iyy="1.76E-04" iyz="6.23E-07" izz="8.96E-05"/>
    </inertial>
  </link>
  <!-- crane_x7_joint_2 -->
  <joint name="crane_x7_shoulder_revolute_part_tilt_joint" type="revolute">
    <origin rpy="0 0 0" xyz="0 0 0.064"/>
    <axis xyz="0 -1 0"/>
    <limit effort="10.0" lower="-1.570795" upper="1.570795" velocity="4.81710873"/>
    <parent link="crane_x7_shoulder_revolute_part_link"/>
    <child link="crane_x7_upper_arm_fixed_part_link"/>
    <dynamics damping="1.0e-6" friction="2.0e-1"/>
  </joint>
  <!-- For gazebo simulation -->
  <transmission name="crane_x7_shoulder_revolute_part_tilt_joint_trans">
    <provideFeedback>true</provideFeedback>
    <implicitSpringDamper>0</implicitSpringDamper>
    <motorTorqueConstant>0.418</motorTorqueConstant>
    <type>transmission_interface/SimpleTransmission</type>
    <joint name="crane_x7_shoulder_revolute_part_tilt_joint">
      <hardwareInterface>hardware_interface/PositionJointInterface</hardwareInterface>
    </joint>
    <actuator name="crane_x7_shoulder_revolute_part_tilt_joint_motor">
      <hardwareInterface>hardware_interface/PositionJointInterface</hardwareInterface>
      <mechanicalReduction>1</mechanicalReduction>
    </actuator>
  </transmission>
  <!-- crane_x7_link_2 -->
  <link name="crane_x7_upper_arm_fixed_part_link">
    <visual>
      <origin rpy="1.570795 0 0" xyz="0 0 0"/>
      <geometry>
        <mesh filename="package://crane_x7_description/meshes/visual/rotating_link_type_1_fixed_part.stl" scale="1 1 1"/>
      </geometry>
      <material name="white"/>
    </visual>
    <collision>
      <origin rpy="1.570795 0 0" xyz="0 0 0"/>
      <geometry>
        <mesh filename="package://crane_x7_description/meshes/collision/rotating_link_type_1_fixed_part.stl" scale="1 1 1"/>
      </geometry>
    </collision>
    <inertial>
      <mass value="0.136"/>
      <origin rpy="1.570795 0 0" xyz="3.10E-05 1.90E-05 3.42E-02"/>
      <inertia ixx="1.68E-04" ixy="2.05E-08" ixz="-4.00E-07" iyy="9.62E-05" iyz="6.24E-08" izz="1.34E-04"/>
    </inertial>
  </link>
  <!-- crane_x7_joint_cover_2_l -->
  <joint name="crane_x7_upper_arm_fixed_part_joint_cover_l_joint" type="fixed">
    <parent link="crane_x7_upper_arm_fixed_part_link"/>
    <child link="crane_x7_upper_arm_fixed_part_joint_cover_l_link"/>
    <origin rpy="0 0 0" xyz="0 0.0316 0"/>
  </joint>
  <!-- crane_x7_link_cover_2_l -->
  <link name="crane_x7_upper_arm_fixed_part_joint_cover_l_link">
    <visual>
      <origin rpy="-1.570795 0 0" xyz="0 0 0"/>
      <geometry>
        <mesh filename="package://crane_x7_description/meshes/visual/joint_cover.stl" scale="1 1 1"/>
      </geometry>
      <material name="red"/>
    </visual>
  </link>
  <!-- crane_x7_joint_cover_2_r -->
  <joint name="crane_x7_upper_arm_fixed_part_joint_cover_r_joint" type="fixed">
    <parent link="crane_x7_upper_arm_fixed_part_link"/>
    <child link="crane_x7_upper_arm_fixed_part_joint_cover_r_link"/>
    <origin rpy="0 0 0" xyz="0 -0.0316 0"/>
  </joint>
  <!-- crane_x7_link_cover_2_r -->
  <link name="crane_x7_upper_arm_fixed_part_joint_cover_r_link">
    <visual>
      <origin rpy="1.570795 0 0" xyz="0 0 0"/>
      <geometry>
        <mesh filename="package://crane_x7_description/meshes/visual/joint_cover.stl" scale="1 1 1"/>
      </geometry>
      <material name="red"/>
    </visual>
  </link>
  <!-- crane_x7_joint_3 -->
  <joint name="crane_x7_upper_arm_revolute_part_twist_joint" type="revolute">
    <origin rpy="0 0 0" xyz="0 0 0.065"/>
    <axis xyz="0 0 1"/>
    <limit effort="4.0" lower="-1.570795" upper="1.570795" velocity="4.81710873"/>
    <parent link="crane_x7_upper_arm_fixed_part_link"/>
    <child link="crane_x7_upper_arm_revolute_part_link"/>
    <dynamics damping="1.0e-6" friction="2.0e-1"/>
  </joint>
  <!-- For gazebo simulation -->
  <transmission name="crane_x7_upper_arm_revolute_part_twist_joint_trans">
    <provideFeedback>true</provideFeedback>
    <implicitSpringDamper>0</implicitSpringDamper>
    <motorTorqueConstant>0.418</motorTorqueConstant>
    <type>transmission_interface/SimpleTransmission</type>
    <joint name="crane_x7_upper_arm_revolute_part_twist_joint">
      <hardwareInterface>hardware_interface/PositionJointInterface</hardwareInterface>
    </joint>
    <actuator name="crane_x7_upper_arm_revolute_part_twist_joint_motor">
      <hardwareInterface>hardware_interface/PositionJointInterface</hardwareInterface>
      <mechanicalReduction>1</mechanicalReduction>
    </actuator>
  </transmission>
  <!-- crane_x7_link_3 -->
  <link name="crane_x7_upper_arm_revolute_part_link">
    <visual>
      <origin rpy="0 0 0" xyz="0 0 0"/>
      <geometry>
        <mesh filename="package://crane_x7_description/meshes/visual/rotating_link_type_1_revolute_part.stl" scale="1 1 1"/>
      </geometry>
      <material name="white"/>
    </visual>
    <collision>
      <origin rpy="0 0 0" xyz="0 0 0"/>
      <geometry>
        <mesh filename="package://crane_x7_description/meshes/collision/rotating_link_type_1_revolute_part.stl" scale="1 1 1"/>
      </geometry>
    </collision>
    <inertial>
      <mass value="0.321"/>
      <origin rpy="0 0 0" xyz="-1.37E-02 -8.10E-05 9.52E-02"/>
      <inertia ixx="1.82E-03" ixy="7.54E-07" ixz="-3.73E-05" iyy="1.88E-03" iyz="4.15E-06" izz="1.59E-04"/>
    </inertial>
  </link>
  <!-- crane_x7_joint_4 -->
  <joint name="crane_x7_upper_arm_revolute_part_rotate_joint" type="revolute">
    <origin rpy="0 0 0" xyz="0 0 0.185"/>
    <axis xyz="0 -1 0"/>
    <limit effort="4.0" lower="-2.80718" upper="0.04141" velocity="4.81710873"/>
    <parent link="crane_x7_upper_arm_revolute_part_link"/>
    <child link="crane_x7_lower_arm_fixed_part_link"/>
    <dynamics damping="1.0e-6" friction="2.0e-1"/>
  </joint>
  <!-- For gazebo simulation -->
  <transmission name="crane_x7_upper_arm_revolute_part_rotate_joint_trans">
    <provideFeedback>true</provideFeedback>
    <implicitSpringDamper>0</implicitSpringDamper>
    <motorTorqueConstant>0.418</motorTorqueConstant>
    <type>transmission_interface/SimpleTransmission</type>
    <joint name="crane_x7_upper_arm_revolute_part_rotate_joint">
      <hardwareInterface>hardware_interface/PositionJointInterface</hardwareInterface>
    </joint>
    <actuator name="crane_x7_upper_arm_revolute_part_rotate_joint_motor">
      <hardwareInterface>hardware_interface/PositionJointInterface</hardwareInterface>
      <mechanicalReduction>1</mechanicalReduction>
    </actuator>
  </transmission>
  <!-- crane_x7_link_4 -->
  <link name="crane_x7_lower_arm_fixed_part_link">
    <visual>
      <origin rpy="1.570795 0 0" xyz="0 0 0"/>
      <geometry>
        <mesh filename="package://crane_x7_description/meshes/visual/rotating_link_type_2_fixed_part.stl" scale="1 1 1"/>
      </geometry>
      <material name="white"/>
    </visual>
    <collision>
      <origin rpy="1.570795 0 0" xyz="0 0 0"/>
      <geometry>
        <mesh filename="package://crane_x7_description/meshes/collision/rotating_link_type_2_fixed_part.stl" scale="1 1 1"/>
      </geometry>
    </collision>
    <inertial>
      <mass value="0.222"/>
      <origin rpy="1.570795 0 0" xyz="-9.39E-03 6.40E-05 8.04E-02"/>
      <inertia ixx="4.89E-04" ixy="-3.90E-06" ixz="8.29E-08" iyy="1.14E-04" iyz="2.82E-06" izz="5.03E-04"/>
    </inertial>
  </link>
  <!-- crane_x7_joint_cover_4_l -->
  <joint name="crane_x7_lower_arm_fixed_part_joint_cover_l_joint" type="fixed">
    <parent link="crane_x7_lower_arm_fixed_part_link"/>
    <child link="crane_x7_lower_arm_fixed_part_joint_cover_l_link"/>
    <origin rpy="0 0 0" xyz="0 0.025 0"/>
  </joint>
  <!-- crane_x7_link_cover_4_l -->
  <link name="crane_x7_lower_arm_fixed_part_joint_cover_l_link">
    <visual>
      <origin rpy="-1.570795 0 0" xyz="0 0 0"/>
      <geometry>
        <mesh filename="package://crane_x7_description/meshes/visual/joint_cover.stl" scale="1 1 1"/>
      </geometry>
      <material name="red"/>
    </visual>
  </link>
  <!-- crane_x7_joint_cover_4_r -->
  <joint name="crane_x7_lower_arm_fixed_part_joint_cover_r_joint" type="fixed">
    <parent link="crane_x7_lower_arm_fixed_part_link"/>
    <child link="crane_x7_lower_arm_fixed_part_joint_cover_r_link"/>
    <origin rpy="0 0 0" xyz="0 -0.025 0"/>
  </joint>
  <!-- crane_x7_link_cover_4_r -->
  <link name="crane_x7_lower_arm_fixed_part_joint_cover_r_link">
    <visual>
      <origin rpy="1.570795 0 0" xyz="0 0 0"/>
      <geometry>
        <mesh filename="package://crane_x7_description/meshes/visual/joint_cover.stl" scale="1 1 1"/>
      </geometry>
      <material name="red"/>
    </visual>
  </link>
  <!-- crane_x7_joint_5 -->
  <joint name="crane_x7_lower_arm_fixed_part_joint" type="revolute">
    <origin rpy="0 0 0" xyz="0 0 0.121"/>
    <axis xyz="0 0 1"/>
    <limit effort="4.0" lower="-2.77343" upper="1.51403" velocity="4.81710873"/>
    <parent link="crane_x7_lower_arm_fixed_part_link"/>
    <child link="crane_x7_lower_arm_revolute_part_link"/>
    <dynamics damping="1.0e-6" friction="2.0e-1"/>
  </joint>
  <!-- For gazebo simulation -->
  <transmission name="crane_x7_lower_arm_fixed_part_joint_trans">
    <provideFeedback>true</provideFeedback>
    <implicitSpringDamper>0</implicitSpringDamper>
    <motorTorqueConstant>0.418</motorTorqueConstant>
    <type>transmission_interface/SimpleTransmission</type>
    <joint name="crane_x7_lower_arm_fixed_part_joint">
      <hardwareInterface>hardware_interface/PositionJointInterface</hardwareInterface>
    </joint>
    <actuator name="crane_x7_lower_arm_fixed_part_joint_motor">
      <hardwareInterface>hardware_interface/PositionJointInterface</hardwareInterface>
      <mechanicalReduction>1</mechanicalReduction>
    </actuator>
  </transmission>
  <!-- crane_x7_link_5 -->
  <link name="crane_x7_lower_arm_revolute_part_link">
    <visual>
      <origin rpy="0 0 0" xyz="0 0 0"/>
      <geometry>
        <mesh filename="package://crane_x7_description/meshes/visual/rotating_link_type_2_revolute_part.stl" scale="1 1 1"/>
      </geometry>
      <material name="white"/>
    </visual>
    <collision>
      <origin rpy="0 0 0" xyz="0 0 0"/>
      <geometry>
        <mesh filename="package://crane_x7_description/meshes/collision/rotating_link_type_2_revolute_part.stl" scale="1 1 1"/>
      </geometry>
    </collision>
    <inertial>
      <mass value="0.207"/>
      <origin rpy="0 0 0" xyz="-8.40E-05 4.62E-04 6.37E-02"/>
      <inertia ixx="2.90E-04" ixy="1.00E-07" ixz="-4.77E-07" iyy="2.57E-04" iyz="-1.69E-05" izz="8.75E-05"/>
    </inertial>
  </link>
  <!-- Left side logo text -->
  <link name="crane_x7_lower_arm_revolute_part_logo_text_l_link">
    <visual>
      <origin rpy="-1.570795 1.570795 0" xyz="0 0 0"/>
      <geometry>
        <mesh filename="package://crane_x7_description/meshes/visual/rtcorp_logo_name.stl" scale="1 1 1"/>
      </geometry>
      <material name="logo_red">
        <color rgba="1.0 0.3 0.3 1.0"/>
      </material>
    </visual>
  </link>
  <joint name="crane_x7_lower_arm_revolute_part_logo_text_l_joint" type="fixed">
    <parent link="crane_x7_lower_arm_revolute_part_link"/>
    <child link="crane_x7_lower_arm_revolute_part_logo_text_l_link"/>
    <origin rpy="0 0 0" xyz="0 0.0345 0.095"/>
  </joint>
  <!-- Left side logo symbol -->
  <link name="crane_x7_lower_arm_revolute_part_logo_symbol_l_link">
    <visual>
      <origin rpy="-1.570795 1.570795 0" xyz="0 0 0"/>
      <geometry>
        <mesh filename="package://crane_x7_description/meshes/visual/rtcorp_logo_rabbit.stl" scale="1 1 1"/>
      </geometry>
      <material name="logo_red"/>
    </visual>
  </link>
  <joint name="crane_x7_lower_arm_revolute_part_logo_symbol_l_joint" type="fixed">
    <parent link="crane_x7_lower_arm_revolute_part_link"/>
    <child link="crane_x7_lower_arm_revolute_part_logo_symbol_l_link"/>
    <origin rpy="0 0 0" xyz="0 0.0345 0.132"/>
  </joint>
  <!-- Right side logo text -->
  <link name="crane_x7_lower_arm_revolute_part_logo_text_r_link">
    <visual>
      <origin rpy="1.570795 -1.570795 0" xyz="0 0 0"/>
      <geometry>
        <mesh filename="package://crane_x7_description/meshes/visual/rtcorp_logo_name.stl" scale="1 1 1"/>
      </geometry>
      <material name="logo_red"/>
    </visual>
  </link>
  <joint name="crane_x7_lower_arm_revolute_part_logo_text_r_joint" type="fixed">
    <parent link="crane_x7_lower_arm_revolute_part_link"/>
    <child link="crane_x7_lower_arm_revolute_part_logo_text_r_link"/>
    <origin rpy="0 0 0" xyz="0 -0.0345 0.104"/>
  </joint>
  <!-- Right side logo symbol -->
  <link name="crane_x7_lower_arm_revolute_part_logo_symbol_r_link">
    <visual>
      <origin rpy="1.570795 -1.570795 0" xyz="0 0 0"/>
      <geometry>
        <mesh filename="package://crane_x7_description/meshes/visual/rtcorp_logo_rabbit.stl" scale="1 1 1"/>
      </geometry>
      <material name="logo_red"/>
    </visual>
  </link>
  <joint name="crane_x7_lower_arm_revolute_part_logo_symbol_r_joint" type="fixed">
    <parent link="crane_x7_lower_arm_revolute_part_link"/>
    <child link="crane_x7_lower_arm_revolute_part_logo_symbol_r_link"/>
    <origin rpy="0 0 0" xyz="0 -0.0345 0.065"/>
  </joint>
  <!-- For gazebo simulation -->
  <gazebo reference="crane_x7_lower_arm_revolute_part_logo_symbol_r_link">
    <material>Gazebo/Red</material>
  </gazebo>
  <gazebo reference="crane_x7_lower_arm_revolute_part_logo_symbol_l_link">
    <material>Gazebo/Red</material>
  </gazebo>
  <gazebo reference="crane_x7_lower_arm_revolute_part_logo_text_r_link">
    <material>Gazebo/Black</material>
  </gazebo>
  <gazebo reference="crane_x7_lower_arm_revolute_part_logo_text_l_link">
    <material>Gazebo/Black</material>
  </gazebo>
  <!-- crane_x7_joint_6 -->
  <joint name="crane_x7_lower_arm_revolute_part_joint" type="revolute">
    <origin rpy="0 0 0" xyz="0 0 0.129"/>
    <axis xyz="0 -1 0"/>
    <limit effort="4.0" lower="-1.570795" upper="1.570795" velocity="4.81710873"/>
    <parent link="crane_x7_lower_arm_revolute_part_link"/>
    <child link="crane_x7_wrist_link"/>
    <dynamics damping="1.0e-6" friction="2.0e-1"/>
  </joint>
  <!-- For gazebo simulation -->
  <transmission name="crane_x7_lower_arm_revolute_part_joint_trans">
    <provideFeedback>true</provideFeedback>
    <implicitSpringDamper>0</implicitSpringDamper>
    <motorTorqueConstant>0.418</motorTorqueConstant>
    <type>transmission_interface/SimpleTransmission</type>
    <joint name="crane_x7_lower_arm_revolute_part_joint">
      <hardwareInterface>hardware_interface/PositionJointInterface</hardwareInterface>
    </joint>
    <actuator name="crane_x7_lower_arm_revolute_part_joint_motor">
      <hardwareInterface>hardware_interface/PositionJointInterface</hardwareInterface>
      <mechanicalReduction>1</mechanicalReduction>
    </actuator>
  </transmission>
  <!-- crane_x7_link_6 -->
  <link name="crane_x7_wrist_link">
    <visual>
      <origin rpy="1.570795 0 0" xyz="0 0 0"/>
      <geometry>
        <mesh filename="package://crane_x7_description/meshes/visual/wrist.stl" scale="1 1 1"/>
      </geometry>
      <material name="white"/>
    </visual>
    <collision>
      <origin rpy="1.570795 0 0" xyz="0 0 0"/>
      <geometry>
        <mesh filename="package://crane_x7_description/meshes/collision/wrist.stl" scale="1 1 1"/>
      </geometry>
    </collision>
    <inertial>
      <mass value="0.14"/>
      <origin rpy="1.570795 0 0" xyz="6.10E-03 8.26E-04 -3.55E-03"/>
      <inertia ixx="4.01E-05" ixy="-2.91E-06" ixz="6.39E-07" iyy="6.13E-05" iyz="-4.90E-07" izz="7.35E-05"/>
    </inertial>
  </link>
  <!-- crane_x7_joint_7 -->
  <joint name="crane_x7_wrist_joint" type="revolute">
    <origin rpy="0 0 0" xyz="0 0 0.019"/>
    <axis xyz="0 0 1"/>
    <limit effort="4.0" lower="-2.96365" upper="2.97132" velocity="4.81710873"/>
    <parent link="crane_x7_wrist_link"/>
    <child link="crane_x7_gripper_base_link"/>
    <dynamics damping="1.0e-6" friction="2.0e-1"/>
  </joint>
  <!-- For gazebo simulation -->
  <transmission name="crane_x7_wrist_joint_trans">
    <provideFeedback>true</provideFeedback>
    <implicitSpringDamper>0</implicitSpringDamper>
    <motorTorqueConstant>0.418</motorTorqueConstant>
    <type>transmission_interface/SimpleTransmission</type>
    <joint name="crane_x7_wrist_joint">
      <hardwareInterface>hardware_interface/PositionJointInterface</hardwareInterface>
    </joint>
    <actuator name="crane_x7_wrist_joint_motor">
      <hardwareInterface>hardware_interface/PositionJointInterface</hardwareInterface>
      <mechanicalReduction>1</mechanicalReduction>
    </actuator>
  </transmission>
  <gazebo>
    <plugin filename="libgazebo_ros_control.so" name="gazebo_ros_control">
      <robotNamespace>/crane_x7</robotNamespace>
      <robotSimType>gazebo_ros_control/DefaultRobotHWSim</robotSimType>
      <legacyModeNS>false</legacyModeNS>
    </plugin>
  </gazebo>
  <gazebo reference="crane_x7_shoulder_fixed_part_link">
    <material>Gazebo/Red</material>
  </gazebo>
  <gazebo reference="crane_x7_shoulder_revolute_part_link">
    <material>Gazebo/White</material>
  </gazebo>
  <gazebo reference="crane_x7_upper_arm_fixed_part_link">
    <material>Gazebo/White</material>
  </gazebo>
  <gazebo reference="crane_x7_upper_arm_revolute_part_link">
    <material>Gazebo/White</material>
  </gazebo>
  <gazebo reference="crane_x7_lower_arm_fixed_part_link">
    <material>Gazebo/White</material>
  </gazebo>
  <gazebo reference="crane_x7_lower_arm_revolute_part_link">
    <material>Gazebo/White</material>
  </gazebo>
  <gazebo reference="crane_x7_wrist_link">
    <material>Gazebo/White</material>
  </gazebo>
  <gazebo reference="crane_x7_upper_arm_fixed_part_joint_cover_l_link">
    <material>Gazebo/Red</material>
  </gazebo>
  <gazebo reference="crane_x7_upper_arm_fixed_part_joint_cover_r_link">
    <material>Gazebo/Red</material>
  </gazebo>
  <gazebo reference="crane_x7_lower_arm_fixed_part_joint_cover_l_link">
    <material>Gazebo/Red</material>
  </gazebo>
  <gazebo reference="crane_x7_lower_arm_fixed_part_joint_cover_r_link">
    <material>Gazebo/Red</material>
  </gazebo>
  <link name="crane_x7_gripper_base_link">
    <visual>
      <origin rpy="0 0 0" xyz="0 0 0"/>
      <geometry>
        <mesh filename="package://crane_x7_description/meshes/visual/wide_two_finger_gripper_actuator.stl" scale="1 1 1"/>
      </geometry>
      <material name="red"/>
    </visual>
    <collision>
      <origin rpy="0 0 0" xyz="0 0 0"/>
      <geometry>
        <mesh filename="package://crane_x7_description/meshes/collision/wide_two_finger_gripper_actuator.stl" scale="1 1 1"/>
      </geometry>
    </collision>
    <inertial>
      <mass value="0.121"/>
      <origin rpy="0 0 0" xyz="1.08E-04 -1.03E-03 2.08E-02"/>
      <inertia ixx="3.20E-05" ixy="-9.45E-08" ixz="2.61E-07" iyy="4.14E-05" iyz="3.88E-07" izz="4.29E-05"/>
    </inertial>
  </link>
  <joint name="crane_x7_gripper_finger_a_joint" type="revolute">
    <origin rpy="0 0 0" xyz="-0.012 0.0 0.024"/>
    <axis xyz="0 -1 0"/>
    <limit effort="4.0" lower="0.0046" upper="1.62601" velocity="4.81710873"/>
    <parent link="crane_x7_gripper_base_link"/>
    <child link="crane_x7_gripper_finger_a_link"/>
    <dynamics damping="1.0e-6" friction="8.0e-1"/>
  </joint>
  <!-- for gazebo -->
  <transmission name="crane_x7_gripper_finger_a_joint_trans">
    <provideFeedback>true</provideFeedback>
    <implicitSpringDamper>0</implicitSpringDamper>
    <motorTorqueConstant>0.418</motorTorqueConstant>
    <type>transmission_interface/SimpleTransmission</type>
    <joint name="crane_x7_gripper_finger_a_joint">
      <hardwareInterface>hardware_interface/PositionJointInterface</hardwareInterface>
    </joint>
    <actuator name="crane_x7_gripper_finger_a_joint_motor">
      <hardwareInterface>hardware_interface/PositionJointInterface</hardwareInterface>
      <mechanicalReduction>1</mechanicalReduction>
    </actuator>
  </transmission>
  <link name="crane_x7_gripper_finger_a_link">
    <visual>
      <origin rpy="1.570795 0 0" xyz="0 0 0"/>
      <geometry>
        <mesh filename="package://crane_x7_description/meshes/visual/wide_two_finger_gripper_finger_a.stl" scale="1 1 1"/>
      </geometry>
      <material name="red"/>
    </visual>
    <collision>
      <origin rpy="1.570795 0 0" xyz="0 0 0"/>
      <geometry>
        <mesh filename="package://crane_x7_description/meshes/collision/wide_two_finger_gripper_finger_a.stl" scale="1 1 1"/>
      </geometry>
    </collision>
    <inertial>
      <mass value="0.0158"/>
      <origin rpy="1.570795 0 0" xyz="-2.65E-03 3.54E-03 2.69E-02"/>
      <inertia ixx="1.01E-05" ixy="-1.97E-07" ixz="-9.89E-08" iyy="4.95E-06" iyz="5.37E-07" izz="6.24E-06"/>
    </inertial>
  </link>
  <joint name="crane_x7_gripper_finger_b_joint" type="revolute">
    <origin rpy="0 0 0" xyz="0.012 0.0 0.024"/>
    <axis xyz="0 1 0"/>
    <limit effort="4.0" lower="0.0046" upper="1.62601" velocity="4.81710873"/>
    <parent link="crane_x7_gripper_base_link"/>
    <child link="crane_x7_gripper_finger_b_link"/>
    <mimic joint="crane_x7_gripper_finger_a_joint"/>
    <dynamics damping="1.0e-6" friction="8.0e-1"/>
  </joint>
  <link name="crane_x7_gripper_finger_b_link">
    <visual>
      <origin rpy="1.570795 0 0" xyz="0 0 0"/>
      <geometry>
        <mesh filename="package://crane_x7_description/meshes/visual/wide_two_finger_gripper_finger_b.stl" scale="1 1 1"/>
      </geometry>
      <material name="red"/>
    </visual>
    <collision>
      <origin rpy="1.570795 0 0" xyz="0 0 0"/>
      <geometry>
        <mesh filename="package://crane_x7_description/meshes/collision/wide_two_finger_gripper_finger_b.stl" scale="1 1 1"/>
      </geometry>
    </collision>
    <inertial>
      <mass value="0.0139"/>
      <origin rpy="1.570795 0 0" xyz="3.01E-03 2.85E-03 3.09E-02"/>
      <inertia ixx="7.48E-06" ixy="3.61E-07" ixz="6.34E-08" iyy="4.09E-06" iyz="2.28E-07" izz="4.37E-06"/>
    </inertial>
  </link>
  <!-- For gazebo simulation -->
  <gazebo>
    <plugin filename="libroboticsgroup_gazebo_mimic_joint_plugin.so" name="crane_x7_gripper_mimic_joint">
      <joint>crane_x7_gripper_finger_a_joint</joint>
      <mimicJoint>crane_x7_gripper_finger_b_joint</mimicJoint>
      <multiplier>1</multiplier>
    </plugin>
  </gazebo>
  <gazebo reference="crane_x7_gripper_base_link">
    <material>Gazebo/Red</material>
  </gazebo>
  <gazebo reference="crane_x7_gripper_finger_a_link">
    <mu1>0.8</mu1>
    <mu2>0.8</mu2>
    <material>Gazebo/Red</material>
  </gazebo>
  <gazebo reference="crane_x7_gripper_finger_b_link">
    <mu1>0.8</mu1>
    <mu2>0.8</mu2>
    <material>Gazebo/Red</material>
  </gazebo>
</robot>

